{"trial_id": "0", "hyperparameters": {"space": [{"class_name": "Int", "config": {"name": "conv_1_filters", "default": null, "conditions": [], "min_value": 32, "max_value": 128, "step": 32, "sampling": "linear"}}, {"class_name": "Int", "config": {"name": "conv_2_filters", "default": null, "conditions": [], "min_value": 64, "max_value": 256, "step": 64, "sampling": "linear"}}, {"class_name": "Int", "config": {"name": "conv_3_filters", "default": null, "conditions": [], "min_value": 128, "max_value": 512, "step": 128, "sampling": "linear"}}, {"class_name": "Int", "config": {"name": "conv_4_filters", "default": null, "conditions": [], "min_value": 256, "max_value": 1024, "step": 256, "sampling": "linear"}}, {"class_name": "Int", "config": {"name": "conv_5_filters", "default": null, "conditions": [], "min_value": 512, "max_value": 2048, "step": 512, "sampling": "linear"}}, {"class_name": "Int", "config": {"name": "dense_units", "default": null, "conditions": [], "min_value": 256, "max_value": 1024, "step": 256, "sampling": "linear"}}, {"class_name": "Float", "config": {"name": "dropout_rate", "default": 0.2, "conditions": [], "min_value": 0.2, "max_value": 0.5, "step": 0.1, "sampling": "linear"}}, {"class_name": "Float", "config": {"name": "learning_rate", "default": 0.0001, "conditions": [], "min_value": 0.0001, "max_value": 0.01, "step": null, "sampling": "log"}}], "values": {"conv_1_filters": 96, "conv_2_filters": 256, "conv_3_filters": 512, "conv_4_filters": 256, "conv_5_filters": 2048, "dense_units": 512, "dropout_rate": 0.30000000000000004, "learning_rate": 0.0014655042671027905}}, "metrics": {"metrics": {}}, "score": null, "best_step": 0, "status": "FAILED", "message": "Traceback (most recent call last):\n  File \"/Users/byron/opt/anaconda3/envs/ODLG4/lib/python3.11/site-packages/keras_tuner/src/engine/base_tuner.py\", line 274, in _try_run_and_update_trial\n    self._run_and_update_trial(trial, *fit_args, **fit_kwargs)\n  File \"/Users/byron/opt/anaconda3/envs/ODLG4/lib/python3.11/site-packages/keras_tuner/src/engine/base_tuner.py\", line 239, in _run_and_update_trial\n    results = self.run_trial(trial, *fit_args, **fit_kwargs)\n              ^^^^^^^^^^^^^^^^^^^^^^^^^^^^^^^^^^^^^^^^^^^^^^\n  File \"/Users/byron/opt/anaconda3/envs/ODLG4/lib/python3.11/site-packages/keras_tuner/src/engine/tuner.py\", line 314, in run_trial\n    obj_value = self._build_and_fit_model(trial, *args, **copied_kwargs)\n                ^^^^^^^^^^^^^^^^^^^^^^^^^^^^^^^^^^^^^^^^^^^^^^^^^^^^^^^^\n  File \"/Users/byron/opt/anaconda3/envs/ODLG4/lib/python3.11/site-packages/keras_tuner/src/engine/tuner.py\", line 233, in _build_and_fit_model\n    results = self.hypermodel.fit(hp, model, *args, **kwargs)\n              ^^^^^^^^^^^^^^^^^^^^^^^^^^^^^^^^^^^^^^^^^^^^^^^\n  File \"/Users/byron/opt/anaconda3/envs/ODLG4/lib/python3.11/site-packages/keras_tuner/src/engine/hypermodel.py\", line 149, in fit\n    return model.fit(*args, **kwargs)\n           ^^^^^^^^^^^^^^^^^^^^^^^^^^\n  File \"/Users/byron/opt/anaconda3/envs/ODLG4/lib/python3.11/site-packages/keras/src/utils/traceback_utils.py\", line 122, in error_handler\n    raise e.with_traceback(filtered_tb) from None\n  File \"/Users/byron/opt/anaconda3/envs/ODLG4/lib/python3.11/site-packages/tensorflow/python/eager/execute.py\", line 59, in quick_execute\n    except TypeError as e:\ntensorflow.python.framework.errors_impl.ResourceExhaustedError: Graph execution error:\n\nDetected at node sequential_1/conv2d_1/convolution defined at (most recent call last):\n  File \"<frozen runpy>\", line 198, in _run_module_as_main\n\n  File \"<frozen runpy>\", line 88, in _run_code\n\n  File \"/Users/byron/opt/anaconda3/envs/ODLG4/lib/python3.11/site-packages/ipykernel_launcher.py\", line 17, in <module>\n\n  File \"/Users/byron/opt/anaconda3/envs/ODLG4/lib/python3.11/site-packages/traitlets/config/application.py\", line 992, in launch_instance\n\n  File \"/Users/byron/opt/anaconda3/envs/ODLG4/lib/python3.11/site-packages/ipykernel/kernelapp.py\", line 701, in start\n\n  File \"/Users/byron/opt/anaconda3/envs/ODLG4/lib/python3.11/site-packages/tornado/platform/asyncio.py\", line 195, in start\n\n  File \"/Users/byron/opt/anaconda3/envs/ODLG4/lib/python3.11/asyncio/base_events.py\", line 607, in run_forever\n\n  File \"/Users/byron/opt/anaconda3/envs/ODLG4/lib/python3.11/asyncio/base_events.py\", line 1922, in _run_once\n\n  File \"/Users/byron/opt/anaconda3/envs/ODLG4/lib/python3.11/asyncio/events.py\", line 80, in _run\n\n  File \"/Users/byron/opt/anaconda3/envs/ODLG4/lib/python3.11/site-packages/ipykernel/kernelbase.py\", line 534, in dispatch_queue\n\n  File \"/Users/byron/opt/anaconda3/envs/ODLG4/lib/python3.11/site-packages/ipykernel/kernelbase.py\", line 523, in process_one\n\n  File \"/Users/byron/opt/anaconda3/envs/ODLG4/lib/python3.11/site-packages/ipykernel/kernelbase.py\", line 429, in dispatch_shell\n\n  File \"/Users/byron/opt/anaconda3/envs/ODLG4/lib/python3.11/site-packages/ipykernel/kernelbase.py\", line 767, in execute_request\n\n  File \"/Users/byron/opt/anaconda3/envs/ODLG4/lib/python3.11/site-packages/ipykernel/ipkernel.py\", line 429, in do_execute\n\n  File \"/Users/byron/opt/anaconda3/envs/ODLG4/lib/python3.11/site-packages/ipykernel/zmqshell.py\", line 549, in run_cell\n\n  File \"/Users/byron/opt/anaconda3/envs/ODLG4/lib/python3.11/site-packages/IPython/core/interactiveshell.py\", line 3051, in run_cell\n\n  File \"/Users/byron/opt/anaconda3/envs/ODLG4/lib/python3.11/site-packages/IPython/core/interactiveshell.py\", line 3106, in _run_cell\n\n  File \"/Users/byron/opt/anaconda3/envs/ODLG4/lib/python3.11/site-packages/IPython/core/async_helpers.py\", line 129, in _pseudo_sync_runner\n\n  File \"/Users/byron/opt/anaconda3/envs/ODLG4/lib/python3.11/site-packages/IPython/core/interactiveshell.py\", line 3311, in run_cell_async\n\n  File \"/Users/byron/opt/anaconda3/envs/ODLG4/lib/python3.11/site-packages/IPython/core/interactiveshell.py\", line 3493, in run_ast_nodes\n\n  File \"/Users/byron/opt/anaconda3/envs/ODLG4/lib/python3.11/site-packages/IPython/core/interactiveshell.py\", line 3553, in run_code\n\n  File \"/var/folders/nv/cddx4y_s46n_4yhxp7v2bb540000gn/T/ipykernel_35278/3706538103.py\", line 70, in <module>\n\n  File \"/Users/byron/opt/anaconda3/envs/ODLG4/lib/python3.11/site-packages/keras_tuner/src/engine/base_tuner.py\", line 234, in search\n\n  File \"/Users/byron/opt/anaconda3/envs/ODLG4/lib/python3.11/site-packages/keras_tuner/src/engine/base_tuner.py\", line 274, in _try_run_and_update_trial\n\n  File \"/Users/byron/opt/anaconda3/envs/ODLG4/lib/python3.11/site-packages/keras_tuner/src/engine/base_tuner.py\", line 239, in _run_and_update_trial\n\n  File \"/Users/byron/opt/anaconda3/envs/ODLG4/lib/python3.11/site-packages/keras_tuner/src/engine/tuner.py\", line 314, in run_trial\n\n  File \"/Users/byron/opt/anaconda3/envs/ODLG4/lib/python3.11/site-packages/keras_tuner/src/engine/tuner.py\", line 233, in _build_and_fit_model\n\n  File \"/Users/byron/opt/anaconda3/envs/ODLG4/lib/python3.11/site-packages/keras_tuner/src/engine/hypermodel.py\", line 149, in fit\n\n  File \"/Users/byron/opt/anaconda3/envs/ODLG4/lib/python3.11/site-packages/keras/src/utils/traceback_utils.py\", line 117, in error_handler\n\n  File \"/Users/byron/opt/anaconda3/envs/ODLG4/lib/python3.11/site-packages/keras/src/backend/tensorflow/trainer.py\", line 318, in fit\n\n  File \"/Users/byron/opt/anaconda3/envs/ODLG4/lib/python3.11/site-packages/keras/src/backend/tensorflow/trainer.py\", line 121, in one_step_on_iterator\n\n  File \"/Users/byron/opt/anaconda3/envs/ODLG4/lib/python3.11/site-packages/keras/src/backend/tensorflow/trainer.py\", line 108, in one_step_on_data\n\n  File \"/Users/byron/opt/anaconda3/envs/ODLG4/lib/python3.11/site-packages/keras/src/backend/tensorflow/trainer.py\", line 51, in train_step\n\n  File \"/Users/byron/opt/anaconda3/envs/ODLG4/lib/python3.11/site-packages/keras/src/utils/traceback_utils.py\", line 117, in error_handler\n\n  File \"/Users/byron/opt/anaconda3/envs/ODLG4/lib/python3.11/site-packages/keras/src/layers/layer.py\", line 882, in __call__\n\n  File \"/Users/byron/opt/anaconda3/envs/ODLG4/lib/python3.11/site-packages/keras/src/utils/traceback_utils.py\", line 117, in error_handler\n\n  File \"/Users/byron/opt/anaconda3/envs/ODLG4/lib/python3.11/site-packages/keras/src/ops/operation.py\", line 46, in __call__\n\n  File \"/Users/byron/opt/anaconda3/envs/ODLG4/lib/python3.11/site-packages/keras/src/utils/traceback_utils.py\", line 156, in error_handler\n\n  File \"/Users/byron/opt/anaconda3/envs/ODLG4/lib/python3.11/site-packages/keras/src/models/sequential.py\", line 209, in call\n\n  File \"/Users/byron/opt/anaconda3/envs/ODLG4/lib/python3.11/site-packages/keras/src/models/functional.py\", line 175, in call\n\n  File \"/Users/byron/opt/anaconda3/envs/ODLG4/lib/python3.11/site-packages/keras/src/ops/function.py\", line 171, in _run_through_graph\n\n  File \"/Users/byron/opt/anaconda3/envs/ODLG4/lib/python3.11/site-packages/keras/src/models/functional.py\", line 556, in call\n\n  File \"/Users/byron/opt/anaconda3/envs/ODLG4/lib/python3.11/site-packages/keras/src/utils/traceback_utils.py\", line 117, in error_handler\n\n  File \"/Users/byron/opt/anaconda3/envs/ODLG4/lib/python3.11/site-packages/keras/src/layers/layer.py\", line 882, in __call__\n\n  File \"/Users/byron/opt/anaconda3/envs/ODLG4/lib/python3.11/site-packages/keras/src/utils/traceback_utils.py\", line 117, in error_handler\n\n  File \"/Users/byron/opt/anaconda3/envs/ODLG4/lib/python3.11/site-packages/keras/src/ops/operation.py\", line 46, in __call__\n\n  File \"/Users/byron/opt/anaconda3/envs/ODLG4/lib/python3.11/site-packages/keras/src/utils/traceback_utils.py\", line 156, in error_handler\n\n  File \"/Users/byron/opt/anaconda3/envs/ODLG4/lib/python3.11/site-packages/keras/src/layers/convolutional/base_conv.py\", line 243, in call\n\n  File \"/Users/byron/opt/anaconda3/envs/ODLG4/lib/python3.11/site-packages/keras/src/layers/convolutional/base_conv.py\", line 233, in convolution_op\n\n  File \"/Users/byron/opt/anaconda3/envs/ODLG4/lib/python3.11/site-packages/keras/src/ops/nn.py\", line 909, in conv\n\n  File \"/Users/byron/opt/anaconda3/envs/ODLG4/lib/python3.11/site-packages/keras/src/backend/tensorflow/nn.py\", line 261, in conv\n\n  File \"/Users/byron/opt/anaconda3/envs/ODLG4/lib/python3.11/site-packages/keras/src/backend/tensorflow/nn.py\", line 231, in _conv\n\nOOM when allocating tensor with shape[32,1022,1022,96] and type float on /job:localhost/replica:0/task:0/device:GPU:0 by allocator Simple allocator\n\t [[{{node sequential_1/conv2d_1/convolution}}]]\nHint: If you want to see a list of allocated tensors when OOM happens, add report_tensor_allocations_upon_oom to RunOptions for current allocation info. This isn't available when running in Eager mode.\n [Op:__inference_one_step_on_iterator_11501]\n"}